Workbook

Sheet Form Responses 
A1: Timestamp | B1: Sr. | C1: Name | D1: Intermediate Score | E1: Problems | F1: Major Problem | G1: Academic problems | H1: Administrative or university management problems | I1: Psychological or emotional stress | J1: Social & Interpersonal Problems | K1: Financial Problems | L1: Accommodation or hostel-related issues | M1: Career & Future Uncertainty | N1: Health and Lifestyle Problems | O1: Stress | P1: Solution | Q1: Additional Comments | R1: Email Address
A2: 45963.629 | B2: 1 | C2: Huda | D2: 1080-1139 | E2: Psychological or emotional stress | F2: Social & Interpersonal Problems | G2: Teaching Style & Understanding: Difficulty understanding lectures, fast teaching pace or unclear explanations, language barriers (English or technical terms). | H2: Facilities: Poor library, Wi-Fi, or lab access. | I2: Stress & Anxiety: Pressure to perform well academically, fear of failure or letting family down. | J2: Making Friends: Shyness or social anxiety, difficulty finding like-minded peers. | K2: Tuition Fees: High or rising costs of education. | L2: Hostel Conditions: Poor hygiene, lack of facilities, or overcrowding. | M2: Future Anxiety: Fear of unemployment or uncertain job market. | N2: Mental Health: Depression, burnout, or chronic stress. | O2: 5 | P2: Khud intelligent hai yeh .inhy zarorat nhi .PHD holder hai phir hi ham hi btaye inko. | Q2: No | R2: hudashahid911@gmail.com
A3: 45963.636 | B3: 2 | C3: Muhammad Sheharyar | D3: 1080-1139 | E3: Academic problems | F3: Academic problems | G3: Study Skills: Poor time management, struggle with note-taking or research work, difficulty adapting from rote learning to conceptual learning. | H3: Information & Guidance: Lack of clarity about rules or procedures, poor orientation or advising system. | I3: Stress & Anxiety: Pressure to perform well academically, fear of failure or letting family down. | J3: Peer Pressure: Pressure to fit in or behave a certain way. | K3: Tuition Fees: High or rising costs of education. | L3: Hostel Conditions: Poor hygiene, lack of facilities, or overcrowding. | M3: Career Guidance: Lack of counseling or information about career options. | N3: Sleep & Nutrition: Poor eating habits or irregular sleep. | O3: 3 | P3: I suggest that increase opportunities for students and poor conditions of hostel will be improved. | R3: msheharyar1885@gmail.com | T3: Major Issues
A4: 45963.644 | B4: 3 | C4: Manahil Umar | D4: 1080-1139 | E4: Academic problems, Administrative or university management problems, Psychological or emotional stress | F4: Administrative or university management problems | G4: Study Skills: Poor time management, struggle with note-taking or research work, difficulty adapting from rote learning to conceptual learning., Course Load: Too many subjects or assignments at once, lack of balance between theory and practical work. | H4: Information & Guidance: Lack of clarity about rules or procedures, poor orientation or advising system., Departmental Communication: Difficulty reaching teachers or office staff., Registration & Timetabling: Complex course registration or schedule clashes. | I4: Stress & Anxiety: Pressure to perform well academically, fear of failure or letting family down. | J4: Making Friends: Shyness or social anxiety, difficulty finding like-minded peers. | K4: Tuition Fees: High or rising costs of education., Books & Supplies: Cost of study materials or gadgets. | L4: Hostel Conditions: Poor hygiene, lack of facilities, or overcrowding. | M4: Career Guidance: Lack of counseling or information about career options., Self-Doubt: Unclear about whether the chosen field suits them. | N4: Sleep & Nutrition: Poor eating habits or irregular sleep., Mental Health: Depression, burnout, or chronic stress. | O4: 3 | P4: To solve these problems, must convey these issues to the concerned dept N ask them to take actions immediately " Might is right" so we have to become might | R4: manahilumar2005@gmail.com | T4: Problem | U4: Number | V4: Percentage
A5: 45963.645 | B5: 4 | C5: Misbah Khalid | D5: 1080-1139 | E5: Academic problems | F5: Academic problems | G5: Teaching Style & Understanding: Difficulty understanding lectures, fast teaching pace or unclear explanations, language barriers (English or technical terms). | H5: Facilities: Poor library, Wi-Fi, or lab access. | I5: Stress & Anxiety: Pressure to perform well academically, fear of failure or letting family down. | J5: Making Friends: Shyness or social anxiety, difficulty finding like-minded peers. | K5: Living Expenses: Hostel, rent, food, transportation. | L5: Hostel Conditions: Poor hygiene, lack of facilities, or overcrowding. | M5: Career Guidance: Lack of counseling or information about career options. | N5: Sleep & Nutrition: Poor eating habits or irregular sleep. | O5: 5 | P5: No | Q5: Pf k tchrs change krdo | R5: amanmisbah350@gmail.com | T5: Academic problems | U5: =COUNTIF('Form Responses '!$F$2:$F$33,T5) -> 13 | V5: =U5/31 -> 0.41935484
A6: 45963.649 | B6: 5 | C6: Abdullah Mustafa | D6: 1020-1079 | E6: Academic problems, Accommodation or hostel-related issues | F6: Academic problems | G6: Teaching Style & Understanding: Difficulty understanding lectures, fast teaching pace or unclear explanations, language barriers (English or technical terms). | H6: Information & Guidance: Lack of clarity about rules or procedures, poor orientation or advising system. | I6: Stress & Anxiety: Pressure to perform well academically, fear of failure or letting family down. | J6: Making Friends: Shyness or social anxiety, difficulty finding like-minded peers., Peer Pressure: Pressure to fit in or behave a certain way. | K6: Living Expenses: Hostel, rent, food, transportation. | L6: Hostel Conditions: Poor hygiene, lack of facilities, or overcrowding., Food & Health: Poor quality or limited food options, falling sick due to new environment. | M6: Career Guidance: Lack of counseling or information about career options. | N6: Sleep & Nutrition: Poor eating habits or irregular sleep., Physical Fitness: Lack of exercise or unhealthy routines. | O6: 4 | P6: There should be guidance related to the assignment and computer submition system for freshers. | R6: abd211224@gmail.com | T6: Administrative or university management problems | U6: =COUNTIF('Form Responses '!$F$2:$F$33,T6) -> 6 | V6: =U6/31 -> 0.19354839
A7: 45963.677 | B7: 6 | C7: Shahram Ali Butt | D7: 960-1019 | E7: Academic problems | F7: Psychological or emotional stress | G7: Course Load: Too many subjects or assignments at once, lack of balance between theory and practical work. | H7: Registration & Timetabling: Complex course registration or schedule clashes. | I7: Stress & Anxiety: Pressure to perform well academically, fear of failure or letting family down. | J7: Making Friends: Shyness or social anxiety, difficulty finding like-minded peers. | K7: Tuition Fees: High or rising costs of education. | L7: Hostel Conditions: Poor hygiene, lack of facilities, or overcrowding. | M7: Future Anxiety: Fear of unemployment or uncertain job market. | N7: Mental Health: Depression, burnout, or chronic stress. | O7: 4 | P7: Less academic stress, Better Guidance about assessment system at University level | R7: shahramalibutt@gmail.com | T7: Psychological or emotional stress | U7: =COUNTIF('Form Responses '!$F$2:$F$33,T7) -> 4 | V7: =U7/31 -> 0.12903226
A8: 45963.685 | B8: 7 | C8: Amna Arshad | D8: 1020-1079 | E8: Academic problems, Psychological or emotional stress | F8: Academic problems | G8: Teaching Style & Understanding: Difficulty understanding lectures, fast teaching pace or unclear explanations, language barriers (English or technical terms)., Course Load: Too many subjects or assignments at once, lack of balance between theory and practical work. | H8: Information & Guidance: Lack of clarity about rules or procedures, poor orientation or advising system. | I8: Stress & Anxiety: Pressure to perform well academically, fear of failure or letting family down., Loneliness & Isolation: Feeling disconnected or left out. | J8: Peer Pressure: Pressure to fit in or behave a certain way. | K8: Living Expenses: Hostel, rent, food, transportation. | L8: Food & Health: Poor quality or limited food options, falling sick due to new environment. | M8: Career Guidance: Lack of counseling or information about career options. | N8: Mental Health: Depression, burnout, or chronic stress. | O8: 3 | P8: Teachers should be more clear about what they teach and about the assignments And appropriate amount of time should be given to do the tasks | R8: ammzfine007@gmail.com | T8: Social & Interpersonal Problems | U8: =COUNTIF('Form Responses '!$F$2:$F$33,T8) -> 1 | V8: =U8/31 -> 0.032258065
A9: 45963.688 | B9: 8 | C9: Amina Kmaran | D9: 1080-1139 | E9: Academic problems, Psychological or emotional stress, Social & Interpersonal Problems | F9: Academic problems | G9: Study Skills: Poor time management, struggle with note-taking or research work, difficulty adapting from rote learning to conceptual learning., Assessment & Exams: Unclear grading system, exam anxiety or poor exam preparation., Course Load: Too many subjects or assignments at once, lack of balance between theory and practical work. | H9: Registration & Timetabling: Complex course registration or schedule clashes. | I9: Stress & Anxiety: Pressure to perform well academically, fear of failure or letting family down., Self-Esteem Issues: Comparing oneself with others, feeling not good enough for university standards. | J9: Making Friends: Shyness or social anxiety, difficulty finding like-minded peers. | K9: Tuition Fees: High or rising costs of education., Books & Supplies: Cost of study materials or gadgets. | L9: Hostel Conditions: Poor hygiene, lack of facilities, or overcrowding., Food & Health: Poor quality or limited food options, falling sick due to new environment. | M9: Career Guidance: Lack of counseling or information about career options., Future Anxiety: Fear of unemployment or uncertain job market. | N9: Sleep & Nutrition: Poor eating habits or irregular sleep. | O9: 4 | P9: Proper academic guidance and time management training should be provided to reduce study pressure. | R9: aminakamran916@gmail.com | T9: Financial problems | U9: =COUNTIF('Form Responses '!$F$2:$F$33,T9) -> 2 | V9: =U9/31 -> 0.064516129
A10: 45963.694 | B10: 9 | C10: Shahmeer Khan | D10: 1020-1079 | E10: Administrative or university management problems | F10: Administrative or university management problems | G10: Course Load: Too many subjects or assignments at once, lack of balance between theory and practical work. | H10: Departmental Communication: Difficulty reaching teachers or office staff., Registration & Timetabling: Complex course registration or schedule clashes., Facilities: Poor library, Wi-Fi, or lab access. | I10: Homesickness: Missing family and home environment., Loneliness & Isolation: Feeling disconnected or left out., Self-Esteem Issues: Comparing oneself with others, feeling not good enough for university standards. | J10: Making Friends: Shyness or social anxiety, difficulty finding like-minded peers., Peer Pressure: Pressure to fit in or behave a certain way., Cultural Adjustment: Adapting to diverse backgrounds, accents, or lifestyles. | K10: Tuition Fees: High or rising costs of education., Books & Supplies: Cost of study materials or gadgets., Part-Time Work: Difficulty balancing job and studies. | L10: Hostel Conditions: Poor hygiene, lack of facilities, or overcrowding. | M10: Self-Doubt: Unclear about whether the chosen field suits them. | N10: Physical Fitness: Lack of exercise or unhealthy routines. | O10: 5 | P10: University system must be updated and changes must be made to facilitate students.University system is very poor and there is almost no facility that are provided to the students. | R10: shahmeerkhan98344@gmail.com | T10: Accommodation or hostel-related issues | U10: =COUNTIF('Form Responses '!$F$2:$F$33,T10) -> 2 | V10: =U10/31 -> 0.064516129
A11: 45963.696 | B11: 10 | C11: Tayyaba | D11: 1080-1139 | E11: Academic problems, Psychological or emotional stress, Career or future uncertainty, Health and lifestyle issues | F11: Academic problems | G11: Teaching Style & Understanding: Difficulty understanding lectures, fast teaching pace or unclear explanations, language barriers (English or technical terms)., Study Skills: Poor time management, struggle with note-taking or research work, difficulty adapting from rote learning to conceptual learning., Course Load: Too many subjects or assignments at once, lack of balance between theory and practical work. | H11: Information & Guidance: Lack of clarity about rules or procedures, poor orientation or advising system., Registration & Timetabling: Complex course registration or schedule clashes., Facilities: Poor library, Wi-Fi, or lab access. | I11: Stress & Anxiety: Pressure to perform well academically, fear of failure or letting family down., Self-Esteem Issues: Comparing oneself with others, feeling not good enough for university standards. | J11: Peer Pressure: Pressure to fit in or behave a certain way. | K11: Tuition Fees: High or rising costs of education., Part-Time Work: Difficulty balancing job and studies. | L11: Commuting: Long travel times or poor transport. | M11: Self-Doubt: Unclear about whether the chosen field suits them., Future Anxiety: Fear of unemployment or uncertain job market. | N11: Sleep & Nutrition: Poor eating habits or irregular sleep., Mental Health: Depression, burnout, or chronic stress. | O11: 5 | P11: Work load should be less and teachers should be teaching and not guiding us. | R11: syedatayyaba.48@gmail.com | T11: Career or future uncertainty | U11: =COUNTIF('Form Responses '!$F$2:$F$33,T11) -> 1 | V11: =U11/31 -> 0.032258065
A12: 45964.265 | B12: 11 | C12: Shzad | D12: 1020-1079 | E12: Academic problems, Career or future uncertainty | F12: Career or future uncertainty | G12: Study Skills: Poor time management, struggle with note-taking or research work, difficulty adapting from rote learning to conceptual learning. | H12: Facilities: Poor library, Wi-Fi, or lab access. | I12: Stress & Anxiety: Pressure to perform well academically, fear of failure or letting family down. | J12: Making Friends: Shyness or social anxiety, difficulty finding like-minded peers., Peer Pressure: Pressure to fit in or behave a certain way. | K12: Tuition Fees: High or rising costs of education., Living Expenses: Hostel, rent, food, transportation., Part-Time Work: Difficulty balancing job and studies. | L12: Hostel Conditions: Poor hygiene, lack of facilities, or overcrowding. | M12: Self-Doubt: Unclear about whether the chosen field suits them. | N12: Physical Fitness: Lack of exercise or unhealthy routines., Mental Health: Depression, burnout, or chronic stress. | O12: 2 | P12: Focus on physical activities for fitness and events for entertainment and must prepare students about career | Q12: Entertaining activities | R12: shazadshazadnazir@gmail.com | T12: Health and lifestyle issues | U12: =COUNTIF('Form Responses '!$F$2:$F$33,T12) -> 2 | V12: =U12/31 -> 0.064516129
A13: 45964.413 | B13: 12 | C13: Muhammad Salahuddin | D13: 1020-1079 | E13: Psychological or emotional stress | F13: Psychological or emotional stress | G13: Teaching Style & Understanding: Difficulty understanding lectures, fast teaching pace or unclear explanations, language barriers (English or technical terms). | H13: Information & Guidance: Lack of clarity about rules or procedures, poor orientation or advising system. | I13: Homesickness: Missing family and home environment. | J13: Cultural Adjustment: Adapting to diverse backgrounds, accents, or lifestyles. | K13: Tuition Fees: High or rising costs of education. | L13: Hostel Conditions: Poor hygiene, lack of facilities, or overcrowding., Food & Health: Poor quality or limited food options, falling sick due to new environment., Roommates: Conflicts or personality mismatches. | M13: Career Guidance: Lack of counseling or information about career options., Self-Doubt: Unclear about whether the chosen field suits them. | N13: Mental Health: Depression, burnout, or chronic stress. | O13: 5 | P13: The University management and faculty must show some kind of leniency towards students as they already struggle with the new environment and the management put an undue stress on their minds. | R13: msalahudin441@gmail.com
A14: 45964.691 | B14: 13 | C14: Hisban Ahmad | D14: 1020-1079 | E14: Accommodation or hostel-related issues | F14: Accommodation or hostel-related issues | G14: Study Skills: Poor time management, struggle with note-taking or research work, difficulty adapting from rote learning to conceptual learning. | H14: Departmental Communication: Difficulty reaching teachers or office staff. | I14: Stress & Anxiety: Pressure to perform well academically, fear of failure or letting family down. | J14: Making Friends: Shyness or social anxiety, difficulty finding like-minded peers., Interaction with Seniors: Ragging, bullying, or intimidation. | K14: Tuition Fees: High or rising costs of education. | L14: Hostel Conditions: Poor hygiene, lack of facilities, or overcrowding., Food & Health: Poor quality or limited food options, falling sick due to new environment. | M14: Future Anxiety: Fear of unemployment or uncertain job market. | N14: Sleep & Nutrition: Poor eating habits or irregular sleep. | O14: 5 | P14: IDK | Q14: No comments | R14: hisbanhamdan2020@gmail.com
A15: 45964.75 | B15: 14 | C15: Muhammad Hassan Qasim Khan | D15: 900-959 | E15: Administrative or university management problems | F15: Administrative or university management problems | G15: Study Skills: Poor time management, struggle with note-taking or research work, difficulty adapting from rote learning to conceptual learning. | H15: Information & Guidance: Lack of clarity about rules or procedures, poor orientation or advising system., Registration & Timetabling: Complex course registration or schedule clashes. | I15: Self-Esteem Issues: Comparing oneself with others, feeling not good enough for university standards. | J15: Peer Pressure: Pressure to fit in or behave a certain way. | K15: Living Expenses: Hostel, rent, food, transportation. | L15: Hostel Conditions: Poor hygiene, lack of facilities, or overcrowding., Food & Health: Poor quality or limited food options, falling sick due to new environment. | M15: Self-Doubt: Unclear about whether the chosen field suits them., Future Anxiety: Fear of unemployment or uncertain job market. | N15: Sleep & Nutrition: Poor eating habits or irregular sleep., Physical Fitness: Lack of exercise or unhealthy routines. | O15: 1 | P15: University Management should be improved | R15: hqk4827@gmail.com
A16: 45964.756 | B16: 15 | C16: Muhammad Bilal | D16: 900-959 | E16: Social & Interpersonal Problems, Health and lifestyle issues | F16: Health and lifestyle issues | G16: Course Load: Too many subjects or assignments at once, lack of balance between theory and practical work. | H16: Registration & Timetabling: Complex course registration or schedule clashes. | I16: Stress & Anxiety: Pressure to perform well academically, fear of failure or letting family down., Loneliness & Isolation: Feeling disconnected or left out. | J16: Making Friends: Shyness or social anxiety, difficulty finding like-minded peers., Peer Pressure: Pressure to fit in or behave a certain way. | K16: Living Expenses: Hostel, rent, food, transportation., Books & Supplies: Cost of study materials or gadgets. | L16: Food & Health: Poor quality or limited food options, falling sick due to new environment., Commuting: Long travel times or poor transport. | M16: Future Anxiety: Fear of unemployment or uncertain job market. | N16: Sleep & Nutrition: Poor eating habits or irregular sleep., Physical Fitness: Lack of exercise or unhealthy routines. | O16: 3 | P16: Making good schedules to manage everything. | R16: bilalramzan561@gmail.com
A17: 45964.759 | B17: 16 | C17: Muhammad Zulqarnain Kamal | D17: 960-1019 | E17: Academic problems, Financial problems, Accommodation or hostel-related issues, Career or future uncertainty | F17: Academic problems | G17: Teaching Style & Understanding: Difficulty understanding lectures, fast teaching pace or unclear explanations, language barriers (English or technical terms)., Course Load: Too many subjects or assignments at once, lack of balance between theory and practical work. | H17: Registration & Timetabling: Complex course registration or schedule clashes., Facilities: Poor library, Wi-Fi, or lab access. | I17: Stress & Anxiety: Pressure to perform well academically, fear of failure or letting family down. | J17: Cultural Adjustment: Adapting to diverse backgrounds, accents, or lifestyles. | K17: Tuition Fees: High or rising costs of education. | L17: Hostel Conditions: Poor hygiene, lack of facilities, or overcrowding. | M17: Future Anxiety: Fear of unemployment or uncertain job market. | N17: Sleep & Nutrition: Poor eating habits or irregular sleep., Mental Health: Depression, burnout, or chronic stress. | O17: 3 | P17: Only those subjects must be taught those can add value in student's career like the complex and deep physics (MWM) must not be taught to Computer Engineering,CS,AI,Cys students. | Q17: Only those subjects must be taught those can add value in student's career like the complex and deep physics (MWM) must not be taught to Computer Engineering,CS,AI,Cys students. And only overview of non-valuable subject is enough for basic understanding. | R17: malikzulqar416@gmail.com
A18: 45964.762 | B18: 17 | C18: Muhammad Haseeb | D18: 1080-1139 | E18: Accommodation or hostel-related issues | F18: Accommodation or hostel-related issues | G18: Assessment & Exams: Unclear grading system, exam anxiety or poor exam preparation. | H18: Registration & Timetabling: Complex course registration or schedule clashes. | I18: Stress & Anxiety: Pressure to perform well academically, fear of failure or letting family down. | J18: Peer Pressure: Pressure to fit in or behave a certain way. | K18: Part-Time Work: Difficulty balancing job and studies. | L18: Hostel Conditions: Poor hygiene, lack of facilities, or overcrowding. | M18: Self-Doubt: Unclear about whether the chosen field suits them. | N18: Sleep & Nutrition: Poor eating habits or irregular sleep. | O18: 2 | P18: University hostels must concern about student mental piece and comfort. Management of uni should create a balance between assignments and workload | Q18: Net issues and hostel food should be improved. | R18: rana124haseeb@gmail.com | T18: Stress
A19: 45964.781 | B19: 18 | C19: Owais | D19: 960-1019 | E19: Administrative or university management problems | F19: Administrative or university management problems | G19: Assessment & Exams: Unclear grading system, exam anxiety or poor exam preparation. | H19: Facilities: Poor library, Wi-Fi, or lab access. | I19: Stress & Anxiety: Pressure to perform well academically, fear of failure or letting family down. | J19: Making Friends: Shyness or social anxiety, difficulty finding like-minded peers. | K19: Tuition Fees: High or rising costs of education. | L19: Food & Health: Poor quality or limited food options, falling sick due to new environment. | M19: Career Guidance: Lack of counseling or information about career options. | N19: Sleep & Nutrition: Poor eating habits or irregular sleep. | O19: 2 | P19: Ok | R19: owaisashfaq572@gmail.com | T19: Stress Level | U19: Count | V19: Percentage
A20: 45964.787 | B20: 19 | C20: Zeeshan Ahmad | D20: 960-1019 | E20: Academic problems, Administrative or university management problems | F20: Administrative or university management problems | G20: Teaching Style & Understanding: Difficulty understanding lectures, fast teaching pace or unclear explanations, language barriers (English or technical terms)., Study Skills: Poor time management, struggle with note-taking or research work, difficulty adapting from rote learning to conceptual learning. | H20: Facilities: Poor library, Wi-Fi, or lab access. | I20: Stress & Anxiety: Pressure to perform well academically, fear of failure or letting family down., Self-Esteem Issues: Comparing oneself with others, feeling not good enough for university standards. | J20: Cultural Adjustment: Adapting to diverse backgrounds, accents, or lifestyles. | K20: Tuition Fees: High or rising costs of education., Part-Time Work: Difficulty balancing job and studies. | L20: Hostel Conditions: Poor hygiene, lack of facilities, or overcrowding. | M20: Career Guidance: Lack of counseling or information about career options. | N20: Mental Health: Depression, burnout, or chronic stress. | O20: 3 | P20: Improve management, teachers should give more chances to students, students should be free to ask any question. Ending the rat race system. | R20: zeegcmspak@gmail.com | T20: 1 | U20: =COUNTIF('Form Responses '!$O$2:$O$33,T20) -> 1 | V20: =U20/32 -> 0.03125
A21: 45964.793 | B21: 20 | C21: Muhammad Usman | D21: 1080-1139 | E21: Academic problems | F21: Academic problems | G21: Assessment & Exams: Unclear grading system, exam anxiety or poor exam preparation. | H21: Information & Guidance: Lack of clarity about rules or procedures, poor orientation or advising system. | I21: Stress & Anxiety: Pressure to perform well academically, fear of failure or letting family down. | J21: Peer Pressure: Pressure to fit in or behave a certain way. | K21: Tuition Fees: High or rising costs of education. | L21: Roommates: Conflicts or personality mismatches. | M21: Career Guidance: Lack of counseling or information about career options. | N21: Physical Fitness: Lack of exercise or unhealthy routines. | O21: 3 | P21: Everything | Q21: No comments | R21: usmanasif3536@gmail.com | T21: 2 | U21: =COUNTIF('Form Responses '!$O$2:$O$33,T21) -> 5 | V21: =U21/32 -> 0.15625
A22: 45964.794 | B22: 21 | C22: Hussain Aftab | D22: 1080-1139 | E22: Psychological or emotional stress, Financial problems, Health and lifestyle issues | F22: Psychological or emotional stress | G22: Teaching Style & Understanding: Difficulty understanding lectures, fast teaching pace or unclear explanations, language barriers (English or technical terms)., Course Load: Too many subjects or assignments at once, lack of balance between theory and practical work. | H22: Registration & Timetabling: Complex course registration or schedule clashes. | I22: Stress & Anxiety: Pressure to perform well academically, fear of failure or letting family down. | J22: Making Friends: Shyness or social anxiety, difficulty finding like-minded peers. | K22: Tuition Fees: High or rising costs of education. | L22: Commuting: Long travel times or poor transport. | M22: Future Anxiety: Fear of unemployment or uncertain job market. | N22: Physical Fitness: Lack of exercise or unhealthy routines., Mental Health: Depression, burnout, or chronic stress. | O22: 3 | P22: 1.Make a better class timetable 2.Teachers should give a clear task rather than giving complete exercise as a work because this dampens the creative thinking 3.Offer more events (Events are almost non-existent in UET) | Q22: UET is a good place to study but it should organize more extra curricular activities It should give its students the confidence that they have come to the right place | R22: oghussain63@gmail.com | T22: 3 | U22: =COUNTIF('Form Responses '!$O$2:$O$33,T22) -> 9 | V22: =U22/32 -> 0.28125
A23: 45964.827 | B23: 22 | C23: Muhammad Haseeb | D23: 960-1019 | E23: Academic problems, Financial problems, Career or future uncertainty, Health and lifestyle issues | F23: Academic problems | G23: Teaching Style & Understanding: Difficulty understanding lectures, fast teaching pace or unclear explanations, language barriers (English or technical terms)., Study Skills: Poor time management, struggle with note-taking or research work, difficulty adapting from rote learning to conceptual learning., Course Load: Too many subjects or assignments at once, lack of balance between theory and practical work. | H23: Information & Guidance: Lack of clarity about rules or procedures, poor orientation or advising system., Departmental Communication: Difficulty reaching teachers or office staff., Facilities: Poor library, Wi-Fi, or lab access. | I23: Stress & Anxiety: Pressure to perform well academically, fear of failure or letting family down., Loneliness & Isolation: Feeling disconnected or left out., Self-Esteem Issues: Comparing oneself with others, feeling not good enough for university standards. | J23: Peer Pressure: Pressure to fit in or behave a certain way., Interaction with Seniors: Ragging, bullying, or intimidation., Cultural Adjustment: Adapting to diverse backgrounds, accents, or lifestyles. | K23: Living Expenses: Hostel, rent, food, transportation. | L23: Hostel Conditions: Poor hygiene, lack of facilities, or overcrowding., Food & Health: Poor quality or limited food options, falling sick due to new environment., Commuting: Long travel times or poor transport. | M23: Career Guidance: Lack of counseling or information about career options., Future Anxiety: Fear of unemployment or uncertain job market. | N23: Sleep & Nutrition: Poor eating habits or irregular sleep., Mental Health: Depression, burnout, or chronic stress. | O23: 4 | P23: No | R23: khanzrider777@gmail.com | T23: 4 | U23: =COUNTIF('Form Responses '!$O$2:$O$33,T23) -> 8 | V23: =U23/32 -> 0.25
A24: 45964.923 | B24: 23 | C24: Yameen Chaudhary | D24: 1140-1200 | E24: Academic problems | F24: Academic problems | G24: Teaching Style & Understanding: Difficulty understanding lectures, fast teaching pace or unclear explanations, language barriers (English or technical terms). | H24: Information & Guidance: Lack of clarity about rules or procedures, poor orientation or advising system. | I24: Stress & Anxiety: Pressure to perform well academically, fear of failure or letting family down. | J24: Making Friends: Shyness or social anxiety, difficulty finding like-minded peers. | K24: Books & Supplies: Cost of study materials or gadgets. | L24: Hostel Conditions: Poor hygiene, lack of facilities, or overcrowding. | M24: Career Guidance: Lack of counseling or information about career options. | N24: Sleep & Nutrition: Poor eating habits or irregular sleep. | O24: 5 | P24: Nothing | R24: yameen.ch66e@gmail.com | T24: 5 | U24: =COUNTIF('Form Responses '!$O$2:$O$33,T24) -> 9 | V24: =U24/32 -> 0.28125
A25: 45965.781 | B25: 24 | C25: Muhammad Moaaz | D25: 1020-1079 | E25: Academic problems, Administrative or university management problems, Psychological or emotional stress, Social & Interpersonal Problems, Financial problems, Accommodation or hostel-related issues, Career or future uncertainty | F25: Academic problems | G25: Teaching Style & Understanding: Difficulty understanding lectures, fast teaching pace or unclear explanations, language barriers (English or technical terms). | H25: Information & Guidance: Lack of clarity about rules or procedures, poor orientation or advising system., Departmental Communication: Difficulty reaching teachers or office staff., Registration & Timetabling: Complex course registration or schedule clashes. | I25: Stress & Anxiety: Pressure to perform well academically, fear of failure or letting family down. | J25: Cultural Adjustment: Adapting to diverse backgrounds, accents, or lifestyles. | K25: Living Expenses: Hostel, rent, food, transportation. | L25: Commuting: Long travel times or poor transport. | M25: Self-Doubt: Unclear about whether the chosen field suits them., Future Anxiety: Fear of unemployment or uncertain job market. | N25: Sleep & Nutrition: Poor eating habits or irregular sleep., Mental Health: Depression, burnout, or chronic stress. | O25: 5 | P25: Get a better staff, management and administration that listens to the Students | R25: ishaaqthekickassdaar@gmail.com
A26: 45965.785 | B26: 25 | C26: Sohaib hassan | D26: 1080-1139 | E26: Academic problems | F26: Academic problems | G26: Study Skills: Poor time management, struggle with note-taking or research work, difficulty adapting from rote learning to conceptual learning. | H26: Registration & Timetabling: Complex course registration or schedule clashes. | I26: Loneliness & Isolation: Feeling disconnected or left out. | J26: Cultural Adjustment: Adapting to diverse backgrounds, accents, or lifestyles. | K26: Part-Time Work: Difficulty balancing job and studies. | L26: Food & Health: Poor quality or limited food options, falling sick due to new environment. | M26: Future Anxiety: Fear of unemployment or uncertain job market. | N26: Physical Fitness: Lack of exercise or unhealthy routines. | O26: 4 | P26: Beleive in allah | Q26: No | R26: sabi1032420@gmail.com
A27: 45965.942 | B27: 26 | C27: Abubakar | D27: 1020-1079 | E27: Academic problems, Administrative or university management problems, Social & Interpersonal Problems | F27: Academic problems | G27: Teaching Style & Understanding: Difficulty understanding lectures, fast teaching pace or unclear explanations, language barriers (English or technical terms)., Assessment & Exams: Unclear grading system, exam anxiety or poor exam preparation., Course Load: Too many subjects or assignments at once, lack of balance between theory and practical work. | H27: Information & Guidance: Lack of clarity about rules or procedures, poor orientation or advising system., Departmental Communication: Difficulty reaching teachers or office staff. | I27: Stress & Anxiety: Pressure to perform well academically, fear of failure or letting family down., Self-Esteem Issues: Comparing oneself with others, feeling not good enough for university standards. | J27: Making Friends: Shyness or social anxiety, difficulty finding like-minded peers., Peer Pressure: Pressure to fit in or behave a certain way. | K27: Tuition Fees: High or rising costs of education. | L27: Hostel Conditions: Poor hygiene, lack of facilities, or overcrowding., Food & Health: Poor quality or limited food options, falling sick due to new environment. | M27: Career Guidance: Lack of counseling or information about career options., Future Anxiety: Fear of unemployment or uncertain job market. | N27: Sleep & Nutrition: Poor eating habits or irregular sleep., Mental Health: Depression, burnout, or chronic stress. | O27: 4 | P27: Reduce the Course load on students because they are not well known with this system and may feel difficulty and can lose their motivation. | Q27: Nill | R27: justtotest7878@gmail.com
A28: 45965.943 | B28: 27 | C28: Shoaib | D28: 1020-1079 | E28: Administrative or university management problems, Psychological or emotional stress | F28: Administrative or university management problems | G28: Teaching Style & Understanding: Difficulty understanding lectures, fast teaching pace or unclear explanations, language barriers (English or technical terms)., Study Skills: Poor time management, struggle with note-taking or research work, difficulty adapting from rote learning to conceptual learning. | H28: Information & Guidance: Lack of clarity about rules or procedures, poor orientation or advising system. | I28: Stress & Anxiety: Pressure to perform well academically, fear of failure or letting family down., Self-Esteem Issues: Comparing oneself with others, feeling not good enough for university standards. | J28: Making Friends: Shyness or social anxiety, difficulty finding like-minded peers., Interaction with Seniors: Ragging, bullying, or intimidation. | K28: Tuition Fees: High or rising costs of education. | L28: Hostel Conditions: Poor hygiene, lack of facilities, or overcrowding., Food & Health: Poor quality or limited food options, falling sick due to new environment. | M28: Career Guidance: Lack of counseling or information about career options. | N28: Sleep & Nutrition: Poor eating habits or irregular sleep., Mental Health: Depression, burnout, or chronic stress. | O28: 2 | P28: Give proper guidance | Q28: No | R28: missionff69@gmail.com
A29: 45965.953 | B29: 28 | C29: Ali Akram | D29: 900-959 | E29: Academic problems, Psychological or emotional stress | F29: Financial problems | G29: Study Skills: Poor time management, struggle with note-taking or research work, difficulty adapting from rote learning to conceptual learning., Course Load: Too many subjects or assignments at once, lack of balance between theory and practical work. | H29: Facilities: Poor library, Wi-Fi, or lab access. | I29: Stress & Anxiety: Pressure to perform well academically, fear of failure or letting family down., Homesickness: Missing family and home environment. | J29: Making Friends: Shyness or social anxiety, difficulty finding like-minded peers. | K29: Living Expenses: Hostel, rent, food, transportation. | L29: Hostel Conditions: Poor hygiene, lack of facilities, or overcrowding., Food & Health: Poor quality or limited food options, falling sick due to new environment. | M29: Career Guidance: Lack of counseling or information about career options., Future Anxiety: Fear of unemployment or uncertain job market. | N29: Sleep & Nutrition: Poor eating habits or irregular sleep. | O29: 4 | P29: Hostels are very poor | R29: ali.akram.dev@gmail.com
A30: 45965.954 | B30: 29 | C30: AKHUNZADA SHOAIB KHAN | D30: 960-1019 | E30: Psychological or emotional stress, Social & Interpersonal Problems, Financial problems, Accommodation or hostel-related issues, Career or future uncertainty | F30: Family problems | G30: Assessment & Exams: Unclear grading system, exam anxiety or poor exam preparation. | H30: Departmental Communication: Difficulty reaching teachers or office staff., Registration & Timetabling: Complex course registration or schedule clashes. | I30: Stress & Anxiety: Pressure to perform well academically, fear of failure or letting family down. | J30: Making Friends: Shyness or social anxiety, difficulty finding like-minded peers. | K30: Tuition Fees: High or rising costs of education. | L30: Commuting: Long travel times or poor transport. | M30: Self-Doubt: Unclear about whether the chosen field suits them. | N30: Physical Fitness: Lack of exercise or unhealthy routines., Mental Health: Depression, burnout, or chronic stress. | O30: 2 | P30: the main reason is stress and poor sleeping rather it's due to study or family maters | Q30: Give you best and enjoy your life 💗 | R30: loveguru09912@gmail.com
A31: 45966.567 | B31: 30 | C31: Mamoona Javed | D31: 1140-1200 | E31: Career or future uncertainty | F31: Psychological or emotional stress | G31: Course Load: Too many subjects or assignments at once, lack of balance between theory and practical work. | H31: Information & Guidance: Lack of clarity about rules or procedures, poor orientation or advising system. | I31: Stress & Anxiety: Pressure to perform well academically, fear of failure or letting family down. | J31: Peer Pressure: Pressure to fit in or behave a certain way. | K31: Tuition Fees: High or rising costs of education. | L31: Hostel Conditions: Poor hygiene, lack of facilities, or overcrowding. | M31: Future Anxiety: Fear of unemployment or uncertain job market. | N31: Mental Health: Depression, burnout, or chronic stress. | O31: 5 | P31: There must be good jobs for us cause if we know that our struggle will be rewarded in future then we can study enthusiastically. | Q31: Proper counselling must be given to freshers | R31: mamoonajaved04@gmail.com
A32: 45966.583 | B32: 31 | C32: Muhammad Abdullah | D32: 1080-1139 | E32: Academic problems, Administrative or university management problems, Psychological or emotional stress, Social & Interpersonal Problems, Financial problems, Accommodation or hostel-related issues, Career or future uncertainty, Health and lifestyle issues | F32: Financial problems | G32: Teaching Style & Understanding: Difficulty understanding lectures, fast teaching pace or unclear explanations, language barriers (English or technical terms)., Study Skills: Poor time management, struggle with note-taking or research work, difficulty adapting from rote learning to conceptual learning., Assessment & Exams: Unclear grading system, exam anxiety or poor exam preparation. | H32: Information & Guidance: Lack of clarity about rules or procedures, poor orientation or advising system., Departmental Communication: Difficulty reaching teachers or office staff., Registration & Timetabling: Complex course registration or schedule clashes. | I32: Stress & Anxiety: Pressure to perform well academically, fear of failure or letting family down., Homesickness: Missing family and home environment., Loneliness & Isolation: Feeling disconnected or left out. | J32: Making Friends: Shyness or social anxiety, difficulty finding like-minded peers., Peer Pressure: Pressure to fit in or behave a certain way., Interaction with Seniors: Ragging, bullying, or intimidation. | K32: Tuition Fees: High or rising costs of education., Living Expenses: Hostel, rent, food, transportation., Books & Supplies: Cost of study materials or gadgets. | L32: Hostel Conditions: Poor hygiene, lack of facilities, or overcrowding., Food & Health: Poor quality or limited food options, falling sick due to new environment., Roommates: Conflicts or personality mismatches. | M32: Career Guidance: Lack of counseling or information about career options., Self-Doubt: Unclear about whether the chosen field suits them. | N32: Sleep & Nutrition: Poor eating habits or irregular sleep., Physical Fitness: Lack of exercise or unhealthy routines. | O32: 4 | P32: Chatgpt is the only way out | Q32: Allow us use chatgpt | R32: itzincrediblez@gmail.com | T32: Marks
A33: 45966.586 | B33: 32 | C33: Awais | D33: 1020-1079 | E33: Health and lifestyle issues | F33: Health and lifestyle issues | G33: Study Skills: Poor time management, struggle with note-taking or research work, difficulty adapting from rote learning to conceptual learning., Course Load: Too many subjects or assignments at once, lack of balance between theory and practical work. | H33: Registration & Timetabling: Complex course registration or schedule clashes. | I33: Homesickness: Missing family and home environment. | J33: Cultural Adjustment: Adapting to diverse backgrounds, accents, or lifestyles. | K33: Living Expenses: Hostel, rent, food, transportation. | L33: Food & Health: Poor quality or limited food options, falling sick due to new environment. | M33: Career Guidance: Lack of counseling or information about career options., Self-Doubt: Unclear about whether the chosen field suits them. | N33: Sleep & Nutrition: Poor eating habits or irregular sleep. | O33: 3 | P33: Communication between students and faculty | R33: awaisstyleonly@gmail.com | T33: Marks | U33: Grade | V33: Count | W33: Percentage
T34: 1140-1200 | U34: A++ | V34: =COUNTIF(D1:D33,T34) -> 2 | W34: =V34/32 -> 0.0625
T35: 1080-1139 | U35: A+ | V35: =COUNTIF(D2:D34,T35) -> 11 | W35: =V35/32 -> 0.34375
T36: 1020-1079 | U36: A | V36: =COUNTIF(D3:D35,T36) -> 10 | W36: =V36/32 -> 0.3125
T37: 960-1019 | U37: B++ | V37: =COUNTIF(D4:D36,T37) -> 6 | W37: =V37/32 -> 0.1875
T38: 900-959 | U38: B+ | V38: =COUNTIF(D5:D37,T38) -> 3 | W38: =V38/32 -> 0.09375
T39: 840-899 | U39: B | V39: =COUNTIF(D6:D38,T39) -> 0 | W39: =V39/32 -> 0
T40: 720-839 | U40: C | V40: =COUNTIF(D7:D39,T40) -> 0 | W40: =V40/32 -> 0
...
